2019-09-10 15:08:43,519 - Exception occurred
Traceback (most recent call last):
  File "f:\git\kw_condition\main.py", line 2365, in <module>
    1/0
ZeroDivisionError: division by zero
2019-09-11 08:20:16,061 - Error Occured
Traceback (most recent call last):
  File "f:\git\kw_condition\main.py", line 2365, in <module>
    1/0
ZeroDivisionError: division by zero
2019-09-11 08:21:10,205 - Error Occured
Traceback (most recent call last):
  File "main.py", line 2365, in <module>
    1/0
ZeroDivisionError: division by zero
2019-09-11 09:08:08,671 - Error Occured
Traceback (most recent call last):
  File "main.py", line 2365, in <module>
    1/0
ZeroDivisionError: division by zero
